<robot name="little red rover">
<link name="base_link"></link>
<joint name="base_link_to_base" type="fixed">
<parent link="base_link"/>
<child link="wheel" />
<origin rpy="0.0 0 0" xyz="0 0 0"/>
</joint>
<link name="wheel">
<collision>
<origin xyz="0.011199999999999583553 -0.070740000000000052838 -0.013200000000000267075" rpy="-1.570796326794896558 -1.9327092177914794838e-29 4.4289166483876419747e-31" />
<geometry>
<mesh filename="package://little_red_rover/description/rover/wheel.stl"/>
</geometry>
</collision>
<visual>
<origin xyz="0 0 0" rpy="0 -0 0" />
<geometry>
<mesh filename="package://little_red_rover/description/rover/wheel_visual.stl"/>
</geometry>
<material name="wheel_material">
<color rgba="0.98039215686274505668 0.71372549019607844922 0.0039215686274509803377 1.0"/>
</material>
</visual>
<inertial>
<origin xyz="0.011199999999999559266 -0.057100136674048194985 -0.013200000000000315648" rpy="0 0 0"/>
<mass value="0.06046549999362351574" />
<inertia ixx="2.3167276380112796375e-05" ixy="2.7231503683372964656e-35"  ixz="8.9549838430956627207e-34" iyy="3.8318422821940750637e-05" iyz="1.5763508006626720733e-34" izz="2.3166562982068076898e-05" />
</inertial>
</link>

<link name="robot_body">
<collision>
<origin xyz="0.014500000000000269618 -0.075000000000000427436 -0.036800000000000047951" rpy="1.570796326794896558 1.87093529720827402e-49 1.570796326794896558" />
<geometry>
<mesh filename="package://little_red_rover/description/rover/skid.stl"/>
</geometry>
</collision>
<collision>
<origin xyz="4.5970172113385388002e-16 -0.0001000000000006256301 -0.064300000000000023803" rpy="-1.5707963267948956698 3.0531133177185065031e-16 5.2041704279295962148e-18" />
<geometry>
<mesh filename="package://little_red_rover/description/rover/tt_motor_mount.stl"/>
</geometry>
</collision>
<collision>
<origin xyz="0.015800000000000265221 -0.075000000000000427436 -0.036800000000000047951" rpy="-1.570796326794896558 1.87093529720827402e-49 1.570796326794896558" />
<geometry>
<mesh filename="package://little_red_rover/description/rover/motor_attachment_shim.stl"/>
</geometry>
</collision>
<collision>
<origin xyz="2.7582103268031232801e-16 -3.5735303605122226145e-16 -0.064299999999999996048" rpy="-1.570796326794896558 1.2818989709841445341e-30 -6.4094948549207226706e-31" />
<geometry>
<mesh filename="package://little_red_rover/description/rover/motor_mount_shim.stl"/>
</geometry>
</collision>
<collision>
<origin xyz="0.014800000000000267802 -0.075000000000000427436 -0.036800000000000047951" rpy="1.570796326794896558 1.87093529720827402e-49 1.570796326794896558" />
<geometry>
<mesh filename="package://little_red_rover/description/rover/lidar_motor.stl"/>
</geometry>
</collision>
<collision>
<origin xyz="0.014800000000000267802 -0.075000000000000427436 -0.036800000000000047951" rpy="1.570796326794896558 1.87093529720827402e-49 1.570796326794896558" />
<geometry>
<mesh filename="package://little_red_rover/description/rover/pcb.stl"/>
</geometry>
</collision>
<collision>
<origin xyz="0.014800000000000267802 -0.075000000000000427436 -0.036800000000000047951" rpy="1.570796326794896558 1.87093529720827402e-49 1.570796326794896558" />
<geometry>
<mesh filename="package://little_red_rover/description/rover/lidar_top.stl"/>
</geometry>
</collision>
<collision>
<origin xyz="-1.5959455978986625269e-16 -1.9949319973733281586e-16 -0.0093000000000001796507" rpy="-1.570796326794896558 4.3790577010150455679e-47 -2.7369110631344132034e-48" />
<geometry>
<mesh filename="package://little_red_rover/description/rover/motor_mount_shim.stl"/>
</geometry>
</collision>
<collision>
<origin xyz="0.014800000000000267802 -0.075000000000000427436 -0.036800000000000047951" rpy="1.570796326794896558 1.87093529720827402e-49 1.570796326794896558" />
<geometry>
<mesh filename="package://little_red_rover/description/rover/motor_attachment_shim.stl"/>
</geometry>
</collision>
<collision>
<origin xyz="8.3266726846886740532e-17 -0.00010000000000015725476 -0.0092999999999999853617" rpy="-1.5707963267948972241 3.0531133177210910087e-16 -6.6613381477509638944e-16" />
<geometry>
<mesh filename="package://little_red_rover/description/rover/tt_motor_mount.stl"/>
</geometry>
</collision>
<collision>
<origin xyz="2.7582103268031232801e-16 -3.5735303605122226145e-16 -0.064299999999999996048" rpy="1.570796326794896558 -4.3790577010150455679e-47 -3.141592653589793116" />
<geometry>
<mesh filename="package://little_red_rover/description/rover/tt_motor_3777_v10.stl"/>
</geometry>
</collision>
<collision>
<origin xyz="2.7582103268031232801e-16 -3.5735303605122226145e-16 -0.064299999999999996048" rpy="1.570796326794896558 -4.3790577010150455679e-47 -3.141592653589793116" />
<geometry>
<mesh filename="package://little_red_rover/description/rover/tt_motor_3777_v10.stl"/>
</geometry>
</collision>
<collision>
<origin xyz="2.7582103268031232801e-16 -3.5735303605122226145e-16 -0.064299999999999996048" rpy="1.570796326794896558 -4.3790577010150455679e-47 -3.141592653589793116" />
<geometry>
<mesh filename="package://little_red_rover/description/rover/tt_motor_3777_v10.stl"/>
</geometry>
</collision>
<collision>
<origin xyz="2.7582103268031232801e-16 -3.5735303605122226145e-16 -0.064299999999999996048" rpy="1.570796326794896558 -4.3790577010150455679e-47 -3.141592653589793116" />
<geometry>
<mesh filename="package://little_red_rover/description/rover/tt_motor_3777_v10.stl"/>
</geometry>
</collision>
<collision>
<origin xyz="2.7582103268031232801e-16 -3.5735303605122226145e-16 -0.064299999999999996048" rpy="1.570796326794896558 -4.3790577010150455679e-47 -3.141592653589793116" />
<geometry>
<mesh filename="package://little_red_rover/description/rover/tt_motor_3777_v10.stl"/>
</geometry>
</collision>
<collision>
<origin xyz="2.7582103268031232801e-16 -3.5735303605122226145e-16 -0.064299999999999996048" rpy="1.570796326794896558 -4.3790577010150455679e-47 -3.141592653589793116" />
<geometry>
<mesh filename="package://little_red_rover/description/rover/tt_motor_3777_v10.stl"/>
</geometry>
</collision>
<collision>
<origin xyz="2.7582103268031232801e-16 -3.5735303605122226145e-16 -0.064299999999999996048" rpy="1.570796326794896558 -4.3790577010150455679e-47 -3.141592653589793116" />
<geometry>
<mesh filename="package://little_red_rover/description/rover/tt_motor_3777_v10.stl"/>
</geometry>
</collision>
<collision>
<origin xyz="2.7582103268031232801e-16 -3.5735303605122226145e-16 -0.064299999999999996048" rpy="1.570796326794896558 -4.3790577010150455679e-47 -3.141592653589793116" />
<geometry>
<mesh filename="package://little_red_rover/description/rover/tt_motor_3777_v10.stl"/>
</geometry>
</collision>
<collision>
<origin xyz="0 0 -0.0092999999999999992395" rpy="-1.570796326794896558 4.3790577010150455679e-47 -2.7369110631344132034e-48" />
<geometry>
<mesh filename="package://little_red_rover/description/rover/tt_motor_3777_v10.stl"/>
</geometry>
</collision>
<collision>
<origin xyz="0 0 -0.0092999999999999992395" rpy="-1.570796326794896558 4.3790577010150455679e-47 -2.7369110631344132034e-48" />
<geometry>
<mesh filename="package://little_red_rover/description/rover/tt_motor_3777_v10.stl"/>
</geometry>
</collision>
<collision>
<origin xyz="0 0 -0.0092999999999999992395" rpy="-1.570796326794896558 4.3790577010150455679e-47 -2.7369110631344132034e-48" />
<geometry>
<mesh filename="package://little_red_rover/description/rover/tt_motor_3777_v10.stl"/>
</geometry>
</collision>
<collision>
<origin xyz="0 0 -0.0092999999999999992395" rpy="-1.570796326794896558 4.3790577010150455679e-47 -2.7369110631344132034e-48" />
<geometry>
<mesh filename="package://little_red_rover/description/rover/tt_motor_3777_v10.stl"/>
</geometry>
</collision>
<collision>
<origin xyz="0 0 -0.0092999999999999992395" rpy="-1.570796326794896558 4.3790577010150455679e-47 -2.7369110631344132034e-48" />
<geometry>
<mesh filename="package://little_red_rover/description/rover/tt_motor_3777_v10.stl"/>
</geometry>
</collision>
<collision>
<origin xyz="0 0 -0.0092999999999999992395" rpy="-1.570796326794896558 4.3790577010150455679e-47 -2.7369110631344132034e-48" />
<geometry>
<mesh filename="package://little_red_rover/description/rover/tt_motor_3777_v10.stl"/>
</geometry>
</collision>
<collision>
<origin xyz="0 0 -0.0092999999999999992395" rpy="-1.570796326794896558 4.3790577010150455679e-47 -2.7369110631344132034e-48" />
<geometry>
<mesh filename="package://little_red_rover/description/rover/tt_motor_3777_v10.stl"/>
</geometry>
</collision>
<collision>
<origin xyz="0 0 -0.0092999999999999992395" rpy="-1.570796326794896558 4.3790577010150455679e-47 -2.7369110631344132034e-48" />
<geometry>
<mesh filename="package://little_red_rover/description/rover/tt_motor_3777_v10.stl"/>
</geometry>
</collision>
<visual>
<origin xyz="0 0 0" rpy="0 -0 0" />
<geometry>
<mesh filename="package://little_red_rover/description/rover/robot_body_visual.stl"/>
</geometry>
<material name="robot_body_material">
<color rgba="0.54600512915027965555 0.54055055757933423433 0.45074002316652139744 1.0"/>
</material>
</visual>
<inertial>
<origin xyz="0.014169548257402428057 -0.049271831748333390355 -0.036800774549974969718" rpy="0 0 0"/>
<mass value="0.20097264605429474016" />
<inertia ixx="0.00031681588396518487209" ixy="4.8027734112456329878e-05"  ixz="-1.8759790496998931619e-09" iyy="0.00013869360392620606339" iyz="8.9644321589029826655e-09" izz="0.00028503969796307357387" />
</inertial>
</link>

<link name="lidar">
<inertial>
<origin xyz="0 0 0" rpy="0 0 0" />
<mass value="1e-9" />
<inertia ixx="0" ixy="0" ixz="0" iyy="0" iyz="0" izz="0" />
</inertial>
</link>
<joint name="lidar_frame" type="fixed">
<origin xyz="0.035085000000000268749 -0.075000000000000552336 -0.036800000000000034073" rpy="-1.570796326794896558 -4.8461212225579047131e-31 1.570796326794896558" />
<parent link="robot_body" />
<child link="lidar" />
<axis xyz="0 0 0"/>
</joint>

<link name="base_footprint">
<inertial>
<origin xyz="0 0 0" rpy="0 0 0" />
<mass value="1e-9" />
<inertia ixx="0" ixy="0" ixz="0" iyy="0" iyz="0" izz="0" />
</inertial>
</link>
<joint name="base_footprint_frame" type="fixed">
<origin xyz="-0.030479999999999826676 -1.2663481374630691789e-16 -0.036800000000000047951" rpy="-1.570796326794896558 -1.87093529720827402e-49 -1.570796326794896558" />
<parent link="robot_body" />
<child link="base_footprint" />
<axis xyz="0 0 0"/>
</joint>

<link name="wheel_2">
<collision>
<origin xyz="0 3.4694469519536141888e-18 0.029940000000000015212" rpy="3.141592653589793116 1.2233992452160792469e-45 3.141592653589793116" />
<geometry>
<mesh filename="package://little_red_rover/description/rover/wheel.stl"/>
</geometry>
</collision>
<visual>
<origin xyz="0 0 0" rpy="0 -0 0" />
<geometry>
<mesh filename="package://little_red_rover/description/rover/wheel_2_visual.stl"/>
</geometry>
<material name="wheel_2_material">
<color rgba="0.98039215686274505668 0.71372549019607844922 0.0039215686274509803377 1.0"/>
</material>
</visual>
<inertial>
<origin xyz="2.2760216245726977947e-17 5.2839999385184637384e-17 0.016300136674048164298" rpy="0 0 0"/>
<mass value="0.06046549999362351574" />
<inertia ixx="2.3167276380112809928e-05" ixy="-3.9569895874516455712e-41"  ixz="2.8342828437142311879e-50" iyy="2.3166562982068063345e-05" iyz="5.7109987015281700423e-37" izz="3.8318422821940737084e-05" />
</inertial>
</link>

<joint name="wheel_left" type="continuous">
<origin xyz="2.7408630920433552092e-16 -3.5735303605122226145e-16 -0.077600000000000002309" rpy="3.141592653589793116 -8.3992934510864465944e-30 -1.5707963267948976682" />
<parent link="robot_body" />
<child link="wheel_2" />
<axis xyz="0 0 1"/>
<limit effort="1" velocity="20" />
<joint_properties friction="0.0"/>
</joint>

<joint name="wheel_right" type="continuous">
<origin xyz="0.011199999999999583553 -0.036800000000000041012 -0.013200000000000263606" rpy="1.570796326794896558 -1.570796326794896558 0" />
<parent link="wheel" />
<child link="robot_body" />
<axis xyz="0 0 1"/>
<limit effort="1" velocity="20" />
<joint_properties friction="0.0"/>
</joint>


</robot>
