<robot name="little red rover">
<link name="base_link"></link>
<joint name="base_link_to_base" type="fixed">
<parent link="base_link"/>
<child link="robot_body" />
<origin rpy="0.0 0 0" xyz="0 0 0"/>
</joint>
<link name="robot_body">
<collision>
<origin xyz="0.086199999999999998845 0 0.0013000000000000018919" rpy="5.9164567891575902922e-31 6.1629758220391558245e-32 -3.141592653589793116" />
<geometry>
<mesh filename="package://little_red_rover/description/rover/skid.stl"/>
</geometry>
</collision>
<collision>
<origin xyz="0.011300000000000209183 0.027499999999999965444 -0.013199999999999803904" rpy="9.992007221626410836e-16 -1.570796326794896336 0" />
<geometry>
<mesh filename="package://little_red_rover/description/rover/tt_motor_mount.stl"/>
</geometry>
</collision>
<collision>
<origin xyz="0.086199999999999998845 0 0.0025999999999999990133" rpy="-3.141592653589793116 6.1629758220391558245e-32 -3.141592653589793116" />
<geometry>
<mesh filename="package://little_red_rover/description/rover/motor_attachment_shim.stl"/>
</geometry>
</collision>
<collision>
<origin xyz="0.011199999999999940906 0.027499999999999948097 -0.013199999999999987785" rpy="4.8461212225579072311e-32 -1.570796326794896558 0" />
<geometry>
<mesh filename="package://little_red_rover/description/rover/motor_mount_shim.stl"/>
</geometry>
</collision>
<collision>
<origin xyz="0.086199999999999998845 0 0.0016000000000000000767" rpy="5.9164567891575902922e-31 6.1629758220391558245e-32 -3.141592653589793116" />
<geometry>
<mesh filename="package://little_red_rover/description/rover/lidar_motor.stl"/>
</geometry>
</collision>
<collision>
<origin xyz="0.086199999999999998845 0 0.0016000000000000000767" rpy="5.9164567891575902922e-31 6.1629758220391558245e-32 -3.141592653589793116" />
<geometry>
<mesh filename="package://little_red_rover/description/rover/pcb.stl"/>
</geometry>
</collision>
<collision>
<origin xyz="0.086199999999999998845 0 0.0016000000000000000767" rpy="5.9164567891575902922e-31 6.1629758220391558245e-32 -3.141592653589793116" />
<geometry>
<mesh filename="package://little_red_rover/description/rover/lidar_top.stl"/>
</geometry>
</collision>
<collision>
<origin xyz="0.011199999999999783046 -0.027499999999999861361 -0.0132000000000004232" rpy="4.8461212225578935465e-32 -1.570796326794896558 0" />
<geometry>
<mesh filename="package://little_red_rover/description/rover/motor_mount_shim.stl"/>
</geometry>
</collision>
<collision>
<origin xyz="0.086199999999999998845 0 0.0016000000000000000767" rpy="5.9164567891575902922e-31 6.1629758220391558245e-32 -3.141592653589793116" />
<geometry>
<mesh filename="package://little_red_rover/description/rover/motor_attachment_shim.stl"/>
</geometry>
</collision>
<collision>
<origin xyz="0.011299999999999740807 -0.02750000000000005565 -0.013200000000000180339" rpy="-6.5919492087118649866e-16 -1.5707963267948958919 0" />
<geometry>
<mesh filename="package://little_red_rover/description/rover/tt_motor_mount.stl"/>
</geometry>
</collision>
<collision>
<origin xyz="0.011199999999999940906 0.027499999999999948097 -0.013199999999999987785" rpy="3.141592653589793116 1.570796326794896558 0" />
<geometry>
<mesh filename="package://little_red_rover/description/rover/tt_motor_3777_v10.stl"/>
</geometry>
</collision>
<collision>
<origin xyz="0.011199999999999940906 0.027499999999999948097 -0.013199999999999987785" rpy="3.141592653589793116 1.570796326794896558 0" />
<geometry>
<mesh filename="package://little_red_rover/description/rover/tt_motor_3777_v10.stl"/>
</geometry>
</collision>
<collision>
<origin xyz="0.011199999999999940906 0.027499999999999948097 -0.013199999999999987785" rpy="3.141592653589793116 1.570796326794896558 0" />
<geometry>
<mesh filename="package://little_red_rover/description/rover/tt_motor_3777_v10.stl"/>
</geometry>
</collision>
<collision>
<origin xyz="0.011199999999999940906 0.027499999999999948097 -0.013199999999999987785" rpy="3.141592653589793116 1.570796326794896558 0" />
<geometry>
<mesh filename="package://little_red_rover/description/rover/tt_motor_3777_v10.stl"/>
</geometry>
</collision>
<collision>
<origin xyz="0.011199999999999940906 0.027499999999999948097 -0.013199999999999987785" rpy="3.141592653589793116 1.570796326794896558 0" />
<geometry>
<mesh filename="package://little_red_rover/description/rover/tt_motor_3777_v10.stl"/>
</geometry>
</collision>
<collision>
<origin xyz="0.011199999999999940906 0.027499999999999948097 -0.013199999999999987785" rpy="3.141592653589793116 1.570796326794896558 0" />
<geometry>
<mesh filename="package://little_red_rover/description/rover/tt_motor_3777_v10.stl"/>
</geometry>
</collision>
<collision>
<origin xyz="0.011199999999999940906 0.027499999999999948097 -0.013199999999999987785" rpy="3.141592653589793116 1.570796326794896558 0" />
<geometry>
<mesh filename="package://little_red_rover/description/rover/tt_motor_3777_v10.stl"/>
</geometry>
</collision>
<collision>
<origin xyz="0.011199999999999940906 0.027499999999999948097 -0.013199999999999987785" rpy="3.141592653589793116 1.570796326794896558 0" />
<geometry>
<mesh filename="package://little_red_rover/description/rover/tt_motor_3777_v10.stl"/>
</geometry>
</collision>
<collision>
<origin xyz="0.011199999999999583553 -0.027500000000000041772 -0.013200000000000263606" rpy="4.8461212225578935465e-32 -1.570796326794896558 0" />
<geometry>
<mesh filename="package://little_red_rover/description/rover/tt_motor_3777_v10.stl"/>
</geometry>
</collision>
<collision>
<origin xyz="0.011199999999999583553 -0.027500000000000041772 -0.013200000000000263606" rpy="4.8461212225578935465e-32 -1.570796326794896558 0" />
<geometry>
<mesh filename="package://little_red_rover/description/rover/tt_motor_3777_v10.stl"/>
</geometry>
</collision>
<collision>
<origin xyz="0.011199999999999583553 -0.027500000000000041772 -0.013200000000000263606" rpy="4.8461212225578935465e-32 -1.570796326794896558 0" />
<geometry>
<mesh filename="package://little_red_rover/description/rover/tt_motor_3777_v10.stl"/>
</geometry>
</collision>
<collision>
<origin xyz="0.011199999999999583553 -0.027500000000000041772 -0.013200000000000263606" rpy="4.8461212225578935465e-32 -1.570796326794896558 0" />
<geometry>
<mesh filename="package://little_red_rover/description/rover/tt_motor_3777_v10.stl"/>
</geometry>
</collision>
<collision>
<origin xyz="0.011199999999999583553 -0.027500000000000041772 -0.013200000000000263606" rpy="4.8461212225578935465e-32 -1.570796326794896558 0" />
<geometry>
<mesh filename="package://little_red_rover/description/rover/tt_motor_3777_v10.stl"/>
</geometry>
</collision>
<collision>
<origin xyz="0.011199999999999583553 -0.027500000000000041772 -0.013200000000000263606" rpy="4.8461212225578935465e-32 -1.570796326794896558 0" />
<geometry>
<mesh filename="package://little_red_rover/description/rover/tt_motor_3777_v10.stl"/>
</geometry>
</collision>
<collision>
<origin xyz="0.011199999999999583553 -0.027500000000000041772 -0.013200000000000263606" rpy="4.8461212225578935465e-32 -1.570796326794896558 0" />
<geometry>
<mesh filename="package://little_red_rover/description/rover/tt_motor_3777_v10.stl"/>
</geometry>
</collision>
<collision>
<origin xyz="0.011199999999999583553 -0.027500000000000041772 -0.013200000000000263606" rpy="4.8461212225578935465e-32 -1.570796326794896558 0" />
<geometry>
<mesh filename="package://little_red_rover/description/rover/tt_motor_3777_v10.stl"/>
</geometry>
</collision>
<visual>
<origin xyz="0 0 0" rpy="0 -0 0" />
<geometry>
<mesh filename="package://little_red_rover/description/rover/robot_body_visual.stl"/>
</geometry>
<material name="robot_body_material">
<color rgba="0.54600512915027976657 0.54055055757933434535 0.45074002316652145295 1.0"/>
</material>
</visual>
<inertial>
<origin xyz="0.060471831748332982581 7.7454997493527447951e-07 0.00096954825740216531854" rpy="0 0 0"/>
<mass value="0.2009726460542947124" />
<inertia ixx="0.00013869360392620598207" ixy="8.9644321589152596802e-09"  ixz="-4.8027734112456350207e-05" iyy="0.00028503969796307346545" iyz="1.8759790497015855734e-09" izz="0.00031681588396518487209" />
</inertial>
</link>

<link name="lidar">
<inertial>
<origin xyz="0 0 0" rpy="0 0 0" />
<mass value="1e-9" />
<inertia ixx="0" ixy="0" ixz="0" iyy="0" iyz="0" izz="0" />
</inertial>
</link>
<joint name="lidar_frame" type="fixed">
<origin xyz="0.086200000000000123745 -1.3877787807814456755e-17 0.021884999999999994735" rpy="-3.141592653589793116 -3.2417252823925967892e-30 -3.141592653589793116" />
<parent link="robot_body" />
<child link="lidar" />
<axis xyz="0 0 0"/>
</joint>

<link name="base_footprint">
<inertial>
<origin xyz="0 0 0" rpy="0 0 0" />
<mass value="1e-9" />
<inertia ixx="0" ixy="0" ixz="0" iyy="0" iyz="0" izz="0" />
</inertial>
</link>
<joint name="base_footprint_frame" type="fixed">
<origin xyz="0.011199999999999710187 0 -0.043680000000000086813" rpy="-5.9164567891575902922e-31 -6.1629758220391558245e-32 4.8461212225578935465e-32" />
<parent link="robot_body" />
<child link="base_footprint" />
<axis xyz="0 0 0"/>
</joint>

<link name="wheel">
<collision>
<origin xyz="0 3.4694469519536141888e-18 0.029940000000000015212" rpy="3.141592653589793116 1.2233992452160792469e-45 3.141592653589793116" />
<geometry>
<mesh filename="package://little_red_rover/description/rover/wheel.stl"/>
</geometry>
</collision>
<visual>
<origin xyz="0 0 0" rpy="0 -0 0" />
<geometry>
<mesh filename="package://little_red_rover/description/rover/wheel_visual.stl"/>
</geometry>
<material name="wheel_material">
<color rgba="0.98039215686274505668 0.71372549019607844922 0.0039215686274509803377 1.0"/>
</material>
</visual>
<inertial>
<origin xyz="2.2758078713237790522e-17 5.2846679174213358489e-17 0.016300136674048160829" rpy="0 0 0"/>
<mass value="0.060465499993623508801" />
<inertia ixx="2.3167276380112820092e-05" ixy="-3.9569895874683503507e-41"  ixz="2.8342828437142326122e-50" iyy="2.3166562982068070122e-05" iyz="5.7109987015281717128e-37" izz="3.8318422821940757413e-05" />
</inertial>
</link>

<joint name="wheel_left" type="continuous">
<origin xyz="0.011199999999999940906 0.040799999999999940481 -0.013199999999999989519" rpy="-1.570796326794896558 1.1379786002410102793e-15 -8.3508322388608672319e-30" />
<parent link="robot_body" />
<child link="wheel" />
<axis xyz="0 0 1"/>
<limit effort="1" velocity="20" />
<joint_properties friction="0.0"/>
</joint>

<link name="wheel_2">
<collision>
<origin xyz="0 3.4694469519536141888e-18 -0.029940000000000022151" rpy="-1.3137173103045198934e-46 1.0760550723461240521e-47 -1.313717310304516004e-45" />
<geometry>
<mesh filename="package://little_red_rover/description/rover/wheel.stl"/>
</geometry>
</collision>
<visual>
<origin xyz="0 0 0" rpy="0 -0 0" />
<geometry>
<mesh filename="package://little_red_rover/description/rover/wheel_2_visual.stl"/>
</geometry>
<material name="wheel_2_material">
<color rgba="0.98039215686274505668 0.71372549019607844922 0.0039215686274509803377 1.0"/>
</material>
</visual>
<inertial>
<origin xyz="-2.2758078713237790522e-17 5.2846679174213358489e-17 -0.016300136674048167768" rpy="0 0 0"/>
<mass value="0.060465499993623508801" />
<inertia ixx="2.3167276380112820092e-05" ixy="-6.0869566822965798449e-50"  ixz="-6.6161998503117786977e-52" iyy="2.3166562982068070122e-05" iyz="-8.0773890174553915328e-51" izz="3.8318422821940757413e-05" />
</inertial>
</link>

<joint name="wheel_right" type="continuous">
<origin xyz="0.011199999999999583553 -0.040800000000000023748 -0.013200000000000263606" rpy="-1.570796326794896558 -1.9327092177914794838e-29 4.4289166483876419747e-31" />
<parent link="robot_body" />
<child link="wheel_2" />
<axis xyz="0 0 1"/>
<limit effort="1" velocity="20" />
<joint_properties friction="0.0"/>
</joint>


</robot>
